Workbook

Sheet Feuil1
A1: N° Affaire: | B1: 230ETELEC | C1: 230ETMECA | D1: 230ETMECNC | E1: 230ETNQ | F1: 230ETREGU | G1: 240RD | H1: 240RDNC | I1: Total
A2: V19355 | B2: {=_xlfn._xlws.FILTER(Projets!B2:I824, (Projets!A2:A824=A2), "")} | C2: 1546.95 | D2: 0 | E2: 2 | F2: 0 | G2: 541.95 | H2: 0 | I2: 2555
A3: =Machines!D1 | B3: {=Machines!B1:C1} | C3: PROJET | D3: {=Machines!E1:AA1} | E3: CLIENT FINAL | F3: DESCRIPTION | G3: REFERENCE | H3: NB MACHINES | I3: MW | J3: KV | K3: CPHI | L3: HZ | M3: TR/MIN | N3: DAL | O3: LFER | P3: NB POLES | Q3: NB ENCOCHES | R3: IC | S3: IM | T3: IP | U3: EEX | V3: Type produit | W3: Produit | X3: Type affaire | Y3: DAS | Z3: Secteur
A4: {=_xlfn._xlws.FILTER(Machines!D2:D1000, (Machines!A2:A1000=Feuil1!A2), "")} | B4: {=_xlfn._xlws.FILTER(Machines!B2:C1000, (Machines!A2:A1000=Feuil1!A2), "")} | C4: VERSALIS-DK | D4: {=_xlfn._xlws.FILTER(Machines!E2:AA1000, (Machines!A2:A1000=Feuil1!A2), "")} | E4: VERSALIS | F4: JEMAC710RS6 | G4: 0 | H4: 1 | I4: 2.5 | J4: 2 | K4: 0.87 | L4: 37.5 | M4: 750 | N4: 93 | O4: 84 | P4: 6 | Q4: 108 | R4: IC8A6W7 | S4: 1001 | T4: 55 | U4: P | V4: ASYNCH | W4: ASYNCH_CAGE | X4: 0 | Y4: MS | Z4: OIL_GAS
A13: Étiquettes de lignes | B13: Nombre de PROJET | E13: Somme de Total Quantity | F13: Étiquettes de colonnes
A14: MIL | B14: 3 | E14: Étiquettes de lignes | F14: 230ETELEC | G14: 230ETMECA | H14: 230ETMECNC | I14: 230ETNQ | J14: 230ETREGU | K14: 240RD | L14: 240RDNC | M14: Total général
A15: ASYNCH | B15: 1 | E15: A15026 | F15: 45.8 | G15: 365.95 | K15: 524.25 | M15: 936
B16: 1 | E16: A15045 | F16: 215.05 | G16: 1377 | I16: 17.25 | K16: 7.7 | M16: 1617
A17: SYNCH | B17: 2 | E17: A15055 | F17: 12 | G17: 245.2 | M17: 257.2
B18: 1 | E18: A15168 | F18: 334.8 | G18: 452.35 | I18: 4 | J18: 31.8 | M18: 822.95
A19: ALT_4P_S | B19: 1 | E19: A15173 | F19: 4.5 | G19: 224.95 | K19: 2 | M19: 231.45
A20: MS | B20: 306 | E20: A15243 | F20: 33.1 | G20: 420.25 | J20: 51.1 | K20: 230.7 | M20: 735.15
A21: ASYNCH | B21: 167 | E21: A15249 | G21: 63.9 | J21: 4 | K21: 227.6 | M21: 295.5
B22: 6 | E22: A15284 | F22: 28.1 | G22: 431.1 | I22: 2 | J22: 1.5 | M22: 462.7
A23: ASYNCH_BAGUES | B23: 7 | E23: A15305 | F23: 12.5 | G23: 66.1 | J23: 0.7 | M23: 79.3
A24: ASYNCH_CAGE | B24: 154 | E24: A15333 | G24: 656.9 | J24: 40 | M24: 696.9
A25: SYNCH | B25: 139 | E25: A15369 | F25: 228.1 | G25: 167.25 | I25: 4 | J25: 19.4 | K25: 213 | M25: 631.75
B26: 35 | E26: A15371 | F26: 20.9 | G26: 3 | J26: 5 | K26: 19.1 | M26: 48
A27: ALT_2P | B27: 7 | E27: A15377 | G27: 190.75 | I27: 3.7 | M27: 194.45
A28: ALT_4P_L | B28: 9 | E28: A15427 | F28: 31.8 | G28: 127.1 | J28: 50.2 | K28: 387.4 | M28: 596.5
A29: ALT_4P_S | B29: 88 | E29: A15469 | G29: 92.6 | M29: 92.6
A30: NUC | B30: 50 | E30: A15470 | G30: 100.9 | M30: 100.9
A31: ASYNCH | B31: 42 | E31: A15477 | F31: 82.8 | G31: 754.25 | K31: 23.8 | M31: 860.85
B32: 1 | E32: A15486 | F32: 60.5 | G32: 7.7 | J32: 15.3 | K32: 79.1 | M32: 162.6
A33: ASYNCH_CAGE | B33: 41 | E33: A15556 | F33: 90.35 | G33: 6 | J33: 7.7 | K33: 64.8 | M33: 168.85
A34: SYNCH | B34: 8 | E34: A15607 | F34: 44 | G34: 620.85 | I34: 29.9 | K34: 45 | M34: 739.75
B35: 4 | E35: A15735 | F35: 40.15 | G35: 1418.3 | I35: 5 | J35: 98.6 | K35: 49.05 | M35: 1611.1
A36: ALT_4P_S | B36: 4 | E36: A15755 | G36: 6 | I36: 3 | K36: 2.7 | M36: 11.7
A37: Total général | B37: 359 | E37: A15766 | G37: 89.05 | K37: 6 | M37: 95.05
E38: A15767 | G38: 38.25 | K38: 6 | M38: 44.25
E39: A15768 | F39: 54.9 | G39: 114.6 | J39: 39.8 | K39: 360.4 | M39: 569.7
E40: A15780 | F40: 27.3 | G40: 153.45 | J40: 3.7 | K40: 54.2 | M40: 238.65
E41: A15857 | F41: 162.5 | G41: 625.75 | I41: 13.55 | J41: 16.7 | M41: 818.5
E42: A15858 | G42: 35.5 | K42: 6 | M42: 41.5
E43: A15922 | F43: 55.3 | G43: 300.8 | I43: 6 | K43: 26.95 | M43: 389.05
E44: A15987 | F44: 88.7 | G44: 143.4 | I44: 2 | J44: 29.5 | K44: 97.25 | M44: 360.85
E45: A16005 | F45: 36.3 | G45: 18.5 | J45: 10 | K45: 26.05 | M45: 90.85
E46: A16013 | F46: 13.6 | G46: 14 | J46: 14.4 | K46: 15.1 | M46: 57.1
E47: A16025 | F47: 121.6 | G47: 233 | I47: 3 | M47: 357.6
E48: A16050 | F48: 152.7 | G48: 648.8 | J48: 86 | K48: 236 | M48: 1123.5
...

Sheet Projets
A1: Projet | B1: 230ETELEC | C1: 230ETMECA | D1: 230ETMECNC | E1: 230ETNQ | F1: 230ETREGU | G1: 240RD | H1: 240RDNC | I1: Total général
A2: A15026 | B2: 45.8 | C2: 365.95 | G2: 524.25 | I2: 936
A3: A15045 | B3: 215.05 | C3: 1377 | E3: 17.25 | G3: 7.7 | I3: 1617
A4: A15055 | B4: 12 | C4: 245.2 | I4: 257.2
A5: A15168 | B5: 334.8 | C5: 452.35 | E5: 4 | F5: 31.8 | I5: 822.95
A6: A15173 | B6: 4.5 | C6: 224.95 | G6: 2 | I6: 231.45
A7: A15243 | B7: 33.1 | C7: 420.25 | F7: 51.1 | G7: 230.7 | I7: 735.15
A8: A15249 | C8: 63.9 | F8: 4 | G8: 227.6 | I8: 295.5
A9: A15284 | B9: 28.1 | C9: 431.1 | E9: 2 | F9: 1.5 | I9: 462.7
A10: A15305 | B10: 12.5 | C10: 66.1 | F10: 0.7 | I10: 79.3
A11: A15333 | C11: 656.9 | F11: 40 | I11: 696.9
A12: A15369 | B12: 228.1 | C12: 167.25 | E12: 4 | F12: 19.4 | G12: 213 | I12: 631.75
A13: A15371 | B13: 20.9 | C13: 3 | F13: 5 | G13: 19.1 | I13: 48
A14: A15377 | C14: 190.75 | E14: 3.7 | I14: 194.45
A15: A15427 | B15: 31.8 | C15: 127.1 | F15: 50.2 | G15: 387.4 | I15: 596.5
A16: A15469 | C16: 92.6 | I16: 92.6
A17: A15470 | C17: 100.9 | I17: 100.9
A18: A15477 | B18: 82.8 | C18: 754.25 | G18: 23.8 | I18: 860.85
A19: A15486 | B19: 60.5 | C19: 7.7 | F19: 15.3 | G19: 79.1 | I19: 162.6
A20: A15556 | B20: 90.35 | C20: 6 | F20: 7.7 | G20: 64.8 | I20: 168.85
A21: A15607 | B21: 44 | C21: 620.85 | E21: 29.9 | G21: 45 | I21: 739.75
A22: A15735 | B22: 40.15 | C22: 1418.3 | E22: 5 | F22: 98.6 | G22: 49.05 | I22: 1611.1
A23: A15755 | C23: 6 | E23: 3 | G23: 2.7 | I23: 11.7
A24: A15766 | C24: 89.05 | G24: 6 | I24: 95.05
A25: A15767 | C25: 38.25 | G25: 6 | I25: 44.25
A26: A15768 | B26: 54.9 | C26: 114.6 | F26: 39.8 | G26: 360.4 | I26: 569.7
A27: A15780 | B27: 27.3 | C27: 153.45 | F27: 3.7 | G27: 54.2 | I27: 238.65
A28: A15857 | B28: 162.5 | C28: 625.75 | E28: 13.55 | F28: 16.7 | I28: 818.5
A29: A15858 | C29: 35.5 | G29: 6 | I29: 41.5
A30: A15922 | B30: 55.3 | C30: 300.8 | E30: 6 | G30: 26.95 | I30: 389.05
A31: A15987 | B31: 88.7 | C31: 143.4 | E31: 2 | F31: 29.5 | G31: 97.25 | I31: 360.85
A32: A16005 | B32: 36.3 | C32: 18.5 | F32: 10 | G32: 26.05 | I32: 90.85
A33: A16013 | B33: 13.6 | C33: 14 | F33: 14.4 | G33: 15.1 | I33: 57.1
A34: A16025 | B34: 121.6 | C34: 233 | E34: 3 | I34: 357.6
A35: A16050 | B35: 152.7 | C35: 648.8 | F35: 86 | G35: 236 | I35: 1123.5
A36: A16054 | B36: 16.4 | C36: 471.3 | E36: 22.4 | F36: 33.1 | G36: 20.25 | I36: 563.45
A37: A16074 | B37: 3 | C37: 425.3 | F37: 32.2 | I37: 460.5
A38: A16083 | B38: 80.7 | C38: 859.4 | E38: 3 | G38: 87.25 | I38: 1030.35
A39: A16136 | B39: 79.9 | C39: 478.6 | E39: 10.4 | F39: 22.1 | G39: 48.9 | I39: 639.9
A40: A16167 | C40: 486.85 | I40: 486.85
...

Sheet Machines
A1: N° Projet | B1: DATE | C1: PROJET | D1: NUMERO | E1: CLIENT | F1: CLIENT FINAL | G1: DESCRIPTION | H1: REFERENCE | I1: NB MACHINES | J1: MW | K1: KV | L1: CPHI | M1: HZ | N1: TR/MIN | O1: DAL | P1: LFER | Q1: NB POLES | R1: NB ENCOCHES | S1: IC | T1: IM | U1: IP | V1: EEX | W1: Type produit | X1: Produit | Y1: Type affaire | Z1: DAS | AA1: Secteur | AB1: Heures projet
A2: A15045 | B2: 40164 | C2: MILLSTONE | D2: M10 | E2: AREVA NP | F2: DOMINION NUCLEAR | I2: 1 | J2: 1 | K2: 4 | L2: 1 | M2: 60 | N2: 300 | O2: 137 | P2: 63 | Q2: 24 | R2: 234 | S2: 0 | T2: 1000 | U2: 23 | V2: - | W2: ASYNCH | Z2: MS | AB2: {=_xlfn._xlws.FILTER(Projets!I$2:I$823,(Projets!A$2:A$823=A2), "")}
A3: A15055 | B3: 40049 | C3: RRA HONG YAN HE 3 | D3: M10 | E3: SBW | F3: CNPE | G3: TNC 630 Ax 4 | H3: EI1491 | I3: 2 | J3: 1 | K3: 6 | L3: 0.9 | M3: 50 | N3: 1500 | O3: 52 | P3: 35 | Q3: 4 | R3: 72 | S3: 0 | T3: 1001 | U3: 54 | V3: - | W3: ASYNCH | X3: ASYNCH_CAGE | Z3: MS | AB3: {=_xlfn._xlws.FILTER(Projets!I$2:I$823,(Projets!A$2:A$823=A3), "")}
A4: A15173 | B4: 40217 | C4: RRA HONG YAN HE 4 | D4: M10 | E4: SBW | F4: CNPE | G4: TNC 630 Ax 4 | H4: A15055 | I4: 2 | J4: 1 | K4: 6 | L4: 0.9 | M4: 50 | N4: 1500 | O4: 52 | P4: 35 | Q4: 4 | R4: 72 | S4: 0 | T4: 1001 | U4: 54 | V4: - | W4: ASYNCH | X4: ASYNCH_CAGE | Z4: MS | AB4: {=_xlfn._xlws.FILTER(Projets!I$2:I$823,(Projets!A$2:A$823=A4), "")}
A5: A15243 | B5: 40297 | C5: SULZER PUMPS IRAN | D5: M10 | E5: SULZER PUMPS UK | F5: ASSALUYE BANDAR ABBAS | G5: JEMAC710TM2_11_50 | I5: 4 | J5: 3.9 | K5: 11 | L5: 0.92 | M5: 50 | N5: 3000 | O5: 62 | P5: 89 | Q5: 2 | R5: 66 | S5: 6A1A1 | T5: 1001 | U5: 55 | V5: - | W5: ASYNCH | X5: ASYNCH_CAGE | Z5: MS | AB5: {=_xlfn._xlws.FILTER(Projets!I$2:I$823,(Projets!A$2:A$823=A5), "")}
A6: A15249 | B6: 40287 | C6: PORT HARCOURT | D6: M10 | E6: CLYDE UNION | F6: NIGERIA | G6: JEMAC 400 TM2_3.15_50 | I6: 1 | J6: 0.53 | K6: 3.15 | L6: 0.92 | M6: 50 | N6: 3000 | O6: 39 | P6: 48 | Q6: 2 | R6: 42 | S6: 6A1A1 | T6: 1001 | U6: 55 | V6: - | W6: ASYNCH | X6: ASYNCH_CAGE | Z6: MS | AB6: {=_xlfn._xlws.FILTER(Projets!I$2:I$823,(Projets!A$2:A$823=A6), "")}
A7: A15305 | B7: 40332 | C7: RRA NING DE 3 ET 4 | D7: M10 | E7: CLYDE UNIONS LTD | F7: CNPEC | G7: TNC 630 Ax 4 | H7: 56X.EI1373 | I7: 4 | J7: 1 | K7: 6 | L7: 0.7 | M7: 50 | N7: 1500 | O7: 52 | P7: 35 | Q7: 4 | R7: 72 | S7: 0 | T7: 1001 | U7: 54 | V7: - | W7: ASYNCH | X7: ASYNCH_CAGE | Z7: MS | AB7: {=_xlfn._xlws.FILTER(Projets!I$2:I$823,(Projets!A$2:A$823=A7), "")}
A8: A15369 | B8: 40400 | C8: FLOWSERVE MOTEUR SEC | D8: M10 | E8: FLOW SERVE | F8: TAISHAN NUCLEAR POWER | G8: JEMAC500TS6_10_50 | I8: 8 | J8: 0.94 | K8: 10 | L8: 0.86 | M8: 50 | N8: 1000 | O8: 63 | P8: 74 | Q8: 6 | R8: 72 | S8: 6A1A1 | T8: 1001 | U8: 55 | V8: - | W8: ASYNCH | X8: ASYNCH_CAGE | Z8: MS | AB8: {=_xlfn._xlws.FILTER(Projets!I$2:I$823,(Projets!A$2:A$823=A8), "")}
A9: A15371 | B9: 40609 | C9: JEMAC 450 ANNABA | D9: M10 | E9: MITTAL ALGERIE | F9: MITTAL ALGERIE | G9: JEMAC 450 AS 4_5.5_50 | I9: 1 | J9: 1 | K9: 5 | L9: 0.87 | M9: 50 | N9: 1500 | O9: 50 | P9: 72 | Q9: 4 | R9: 60 | S9: 0A1 | T9: 1001 | U9: 23 | V9: - | W9: ASYNCH | X9: ASYNCH_CAGE | Z9: MS | AB9: {=_xlfn._xlws.FILTER(Projets!I$2:I$823,(Projets!A$2:A$823=A9), "")}
A10: A15427 | B10: 40507 | C10: NAMA_CHEMICALS | D10: L03 | E10: JEUMONT ELECTRIC INDIA | F10: FLOWSERVE | I10: 3 | J10: 1 | K10: 4 | L10: 0.81 | M10: 60 | N10: 900 | O10: 64 | P10: 114 | Q10: 8 | R10: 96 | S10: 6A1A1 | T10: 3011 | U10: 55 | V10: - | W10: ASYNCH | Z10: MS | AB10: {=_xlfn._xlws.FILTER(Projets!I$2:I$823,(Projets!A$2:A$823=A10), "")}
A11: A15427 | B11: 40507 | C11: NAMA_CHEMICALS | D11: L02 | E11: JEUMONT ELECTRIC INDIA | F11: NAMA_CHEMICALS | I11: 3 | J11: 1 | K11: 4 | L11: 0.78 | M11: 60 | N11: 720 | O11: 65 | P11: 79 | Q11: 10 | R11: 120 | S11: 6A1A1 | T11: 3011 | U11: 55 | V11: - | W11: ASYNCH | Z11: MS | AB11: {=_xlfn._xlws.FILTER(Projets!I$2:I$823,(Projets!A$2:A$823=A11), "")}
A12: A15427 | B12: 40506 | C12: NAMA CHEMICALS H355 4P | D12: L01 | E12: FLOWSERVE | F12: NAMA | G12: JEMAC355TS4_4_60 | I12: 3 | J12: 0.315 | K12: 4 | L12: 0.88 | M12: 60 | N12: 1800 | O12: 40 | P12: 46 | Q12: 4 | R12: 48 | S12: 6A1A1 | T12: 1001 | U12: 55 | V12: - | W12: ASYNCH | X12: ASYNCH_CAGE | Z12: MS | AB12: {=_xlfn._xlws.FILTER(Projets!I$2:I$823,(Projets!A$2:A$823=A12), "")}
A13: A15469 | B13: 40511 | C13: RRA FANGCHENGGANG UNIT 1 | D13: M10 | E13: SBW | F13: CNPE | G13: TNC 630 Ax 4 | H13: A15173 | I13: 2 | J13: 1 | K13: 6 | L13: 0.9 | M13: 50 | N13: 1500 | O13: 52 | P13: 35 | Q13: 4 | R13: 72 | S13: 0 | T13: 1001 | U13: 54 | V13: - | W13: ASYNCH | X13: ASYNCH_CAGE | Z13: MS | AB13: {=_xlfn._xlws.FILTER(Projets!I$2:I$823,(Projets!A$2:A$823=A13), "")}
A14: A15470 | B14: 40511 | C14: RRA YANGJIANG UNIT 3 | D14: M10 | E14: SBW | F14: CNPE | G14: TNC 630 Ax 4 | H14: A15173 | I14: 2 | J14: 1 | K14: 6 | L14: 0.9 | M14: 50 | N14: 1500 | O14: 52 | P14: 35 | Q14: 4 | R14: 72 | S14: 0 | T14: 1001 | U14: 54 | V14: - | W14: ASYNCH | X14: ASYNCH_CAGE | Z14: MS | AB14: {=_xlfn._xlws.FILTER(Projets!I$2:I$823,(Projets!A$2:A$823=A14), "")}
A15: A15486 | B15: 40560 | C15: PAQUEBOT H33 - 2 JEMAC500 | D15: M10 | E15: STX FRANCE | F15: HAPAG LLOYD | G15: JEMAC 500 T S 6-6.6-60 | I15: 2 | J15: 1.5 | K15: 6.6 | L15: 0.85 | M15: 60 | N15: 1200 | O15: 64 | P15: 64 | Q15: 6 | R15: 71 | S15: 6A1A1 | T15: 3011 | U15: 44 | V15: - | W15: ASYNCH | X15: ASYNCH_CAGE | Z15: MS | AB15: {=_xlfn._xlws.FILTER(Projets!I$2:I$823,(Projets!A$2:A$823=A15), "")}
A16: A15534 | B16: 40570 | C16: PORT HARCOURT 2 | D16: M10 | E16: CLYDE UNION | F16: NNPC | G16: JEMAC 400 TM2-3.15-50 dans carcasse HA450 | H16: A15249 | I16: 1 | J16: 0.53 | K16: 3.15 | L16: 0.92 | M16: 50 | N16: 3000 | O16: 39 | P16: 48 | Q16: 2 | R16: 42 | S16: 6A1A1 | T16: 1001 | U16: 55 | V16: - | W16: ASYNCH | X16: ASYNCH_CAGE | Z16: MS | AB16: {=_xlfn._xlws.FILTER(Projets!I$2:I$823,(Projets!A$2:A$823=A16), "")}
A17: A15556 | B17: 40599 | C17: ESSAR | D17: M10 | E17: JE INDIA | F17: ESSAR PROJECTS | G17: JEMAC 500 TS 12_6.6_50 | I17: 5 | J17: 1 | K17: 6.6 | L17: 0.7 | M17: 50 | N17: 500 | O17: 656 | P17: 109 | Q17: 12 | R17: 108 | S17: 6A1A1 | T17: 1001 | U17: 55 | V17: - | W17: ASYNCH | X17: ASYNCH_CAGE | Z17: MS | AB17: {=_xlfn._xlws.FILTER(Projets!I$2:I$823,(Projets!A$2:A$823=A17), "")}
A18: A15766 | B18: 40976 | C18: RRA YANGJIANG UNIT 4 | D18: M10 | E18: SBW | F18: CNPE | G18: TNC 630 Ax 4 | H18: A15470 | I18: 2 | J18: 1 | K18: 6 | L18: 0.9 | M18: 50 | N18: 1500 | O18: 52 | P18: 35 | Q18: 4 | R18: 72 | S18: 0 | T18: 1001 | U18: 54 | V18: - | W18: ASYNCH | X18: ASYNCH_CAGE | Z18: MS | AB18: {=_xlfn._xlws.FILTER(Projets!I$2:I$823,(Projets!A$2:A$823=A18), "")}
A19: A15767 | B19: 40976 | C19: RRA FANGCHENGGANG UNIT 2 | D19: M10 | E19: SBW | F19: CNPE | G19: TNC 630 Ax 4 | H19: A15469 | I19: 2 | J19: 1 | K19: 6 | L19: 0.9 | M19: 50 | N19: 1500 | O19: 52 | P19: 35 | Q19: 4 | R19: 72 | S19: 0 | T19: 1001 | U19: 54 | V19: - | W19: ASYNCH | X19: ASYNCH_CAGE | Z19: MS | AB19: {=_xlfn._xlws.FILTER(Projets!I$2:I$823,(Projets!A$2:A$823=A19), "")}
A20: A15768 | B20: 40841 | C20: SITECH ASYNCHRONE K6501 | D20: M10 | E20: SITECH | F20: SITECH | G20: JEMAC 800TL16 | I20: 1 | J20: 2.2 | K20: 10 | L20: 0.82 | M20: 50 | N20: 375 | O20: 80 | P20: 100 | Q20: 16 | R20: 72 | S20: 6A1A1 | T20: 1005 | U20: 55 | V20: N | W20: ASYNCH | X20: ASYNCH_CAGE | Z20: MS | AA20: OIL_GAS | AB20: {=_xlfn._xlws.FILTER(Projets!I$2:I$823,(Projets!A$2:A$823=A20), "")}
A21: A15780 | B21: 40854 | C21: STX MN33 THRUSTER | D21: M10 | E21: STX | F21: MARINE FÃ‰DÃ‰RATION RUSSIE | G21: JEMAC 500 AS6_6.6_50 | I21: 2 | J21: 1.5 | K21: 6 | L21: 0.86 | M21: 50 | N21: 1000 | O21: 63 | P21: 64 | Q21: 6 | R21: 90 | S21: 0A1 | T21: 3011 | U21: 23 | V21: - | W21: ASYNCH | X21: ASYNCH_CAGE | Z21: MS | AB21: {=_xlfn._xlws.FILTER(Projets!I$2:I$823,(Projets!A$2:A$823=A21), "")}
A22: A15857 | B22: 40961 | C22: JEMAC 560 DEWA | D22: M10 | E22: DEWA | F22: DEWA | G22: JEMAC 560 TS 12-6.6-50 | I22: 1 | J22: 0.99 | K22: 6.6 | L22: 0.79 | M22: 50 | N22: 500 | O22: 75 | P22: 114 | Q22: 12 | R22: 108 | S22: 5A1A1 | T22: 3011 | U22: 55 | V22: - | W22: ASYNCH | X22: ASYNCH_CAGE | Z22: MS | AB22: {=_xlfn._xlws.FILTER(Projets!I$2:I$823,(Projets!A$2:A$823=A22), "")}
A23: A15858 | B23: 40976 | C23: RRA FUQING UNIT 3-4 | D23: M10 | E23: CLYDE UNION LTD | F23: CNPEC | G23: TNC 630 Ax 4 | H23: EI1493 | I23: 4 | J23: 1 | K23: 6 | L23: 0.9 | M23: 50 | N23: 1500 | O23: 52 | P23: 35 | Q23: 4 | R23: 72 | S23: 0 | T23: 1001 | U23: 54 | V23: - | W23: ASYNCH | X23: ASYNCH_CAGE | Z23: MS | AB23: {=_xlfn._xlws.FILTER(Projets!I$2:I$823,(Projets!A$2:A$823=A23), "")}
A24: A15987 | B24: 41053 | C24: TERMOMECCANICA TOMBAK | D24: M10 | E24: TM.P.SPA TERMOMECCANICA | F24: MAPNA | I24: 5 | J24: 2.05 | K24: 6.6 | L24: 0.78 | M24: 50 | N24: 428 | O24: 96 | P24: 139 | Q24: 14 | R24: 126 | S24: 6A1A1 | T24: 1001 | U24: 55 | V24: - | W24: ASYNCH | Z24: MS | AB24: {=_xlfn._xlws.FILTER(Projets!I$2:I$823,(Projets!A$2:A$823=A24), "")}
A25: A16005 | B25: 41092 | C25: MOTEURS JEMAC 400 | D25: M10 | E25: MEKEM MAKINA OTOMASYON | F25: MEKEM MAKINA | G25: JEMAC 400 TL 4-6-50 | I25: 6 | J25: 1 | K25: 6 | L25: 0.88 | M25: 50 | N25: 1500 | O25: 46 | P25: 78 | Q25: 4 | R25: 60 | S25: 6A1A1 | T25: 1001 | U25: 55 | V25: E | W25: ASYNCH | X25: ASYNCH_CAGE | Z25: MS | AA25: OIL_GAS | AB25: {=_xlfn._xlws.FILTER(Projets!I$2:I$823,(Projets!A$2:A$823=A25), "")}
A26: A16013 | B26: 41082 | C26: TEST BENCH JEI | D26: M10 | E26: JEUMONT INDIA | F26: JEUMONT INDIA | G26: Moteur d entrainement sur plateforme d'essai | I26: 1 | J26: 0.4 | K26: 2 | L26: 0.8 | M26: 60 | N26: 1200 | O26: 46 | P26: 57 | Q26: 6 | R26: 57 | S26: 0A1 | T26: 1001 | U26: 23 | V26: - | W26: ASYNCH | Z26: MS | AB26: {=_xlfn._xlws.FILTER(Projets!I$2:I$823,(Projets!A$2:A$823=A26), "")}
A27: A16050 | B27: 42431 | C27: JEMAC 710 TL4 | D27: M10 | E27: KARKHEH | F27: KARKHEH | G27: JEMAC 710 TL4 | I27: 3 | J27: 4 | K27: 11 | L27: 0.89 | M27: 50 | N27: 1500 | O27: 87 | P27: 114 | Q27: 4 | R27: 72 | S27: 6A1A1 | T27: 1001 | U27: 55 | V27: E | W27: ASYNCH | X27: ASYNCH_CAGE | Z27: MS | AA27: OIL_GAS | AB27: {=_xlfn._xlws.FILTER(Projets!I$2:I$823,(Projets!A$2:A$823=A27), "")}
A28: A16325 | B28: 41479 | C28: RRA HAINAN | D28: M10 | E28: SPX ECOSSE | F28: HAINAN CHINE | G28: TNC 560-Cy-4 | I28: 4 | J28: 0.225 | K28: 6 | L28: 0.87 | M28: 50 | N28: 1500 | O28: 45 | P28: 41 | Q28: 4 | R28: 66 | S28: 5A1A1 | T28: 1001 | U28: 55 | V28: - | W28: ASYNCH | X28: ASYNCH_CAGE | Z28: MS | AB28: {=_xlfn._xlws.FILTER(Projets!I$2:I$823,(Projets!A$2:A$823=A28), "")}
A29: A16341 | B29: 41536 | C29: RECHANGE TERGA 14P | D29: M20 | E29: ALSTOM | F29: ALSTOM | G29: JEMAC500TS14_6.6_50 | H29: 56X.EI1463A2 | I29: 1 | J29: 0.615 | K29: 6.6 | L29: 0.74 | M29: 50 | N29: 428 | O29: 69 | P29: 114 | Q29: 14 | R29: 126 | S29: 6A1A1 | T29: 3011 | U29: 55 | V29: - | W29: ASYNCH | X29: ASYNCH_CAGE | Z29: MS | AB29: {=_xlfn._xlws.FILTER(Projets!I$2:I$823,(Projets!A$2:A$823=A29), "")}
A30: A16341 | B30: 41536 | C30: RECHANGE TERGA 12P | D30: M10 | E30: ALSTOM | F30: ALSTOM | G30: JEMAC500TS12-6.6-50 | H30: 56X.EI1463A1 | I30: 1 | J30: 0.8 | K30: 6.6 | L30: 0.74 | M30: 50 | N30: 500 | O30: 67 | P30: 114 | Q30: 12 | R30: 108 | S30: 6A1A1 | T30: 3011 | U30: 55 | V30: - | W30: ASYNCH | X30: ASYNCH_CAGE | Z30: MS | AB30: {=_xlfn._xlws.FILTER(Projets!I$2:I$823,(Projets!A$2:A$823=A30), "")}
A31: A16380 | B31: 41529 | C31: PORT ELISABETH | D31: M10 | E31: LINDE AG | F31: LINDE AG | G31: JEMAC 630 RL2-11-50 | I31: 1 | J31: 3 | K31: 11 | L31: 0.9 | M31: 50 | N31: 3000 | O31: 56 | P31: 74 | Q31: 2 | R31: 60 | S31: 8A1W7 | T31: 1001 | U31: 54 | V31: - | W31: ASYNCH | X31: ASYNCH_CAGE | Z31: MS | AB31: {=_xlfn._xlws.FILTER(Projets!I$2:I$823,(Projets!A$2:A$823=A31), "")}
A32: A16406 | B32: 41787 | C32: JEMAC630TL16 VERTICAL | D32: M10 | E32: FLOWSERVE | F32: FLOWSERVE | G32: JEMAC630TL16-5.5-50 | H32: 56X.EI1377 | I32: 1 | J32: 0.85 | K32: 5.5 | L32: 0.79 | M32: 50 | N32: 375 | O32: 86 | P32: 114 | Q32: 16 | R32: 144 | S32: 6A1A1 | T32: 3011 | U32: 54 | V32: - | W32: ASYNCH | X32: ASYNCH_CAGE | Z32: MS | AB32: {=_xlfn._xlws.FILTER(Projets!I$2:I$823,(Projets!A$2:A$823=A32), "")}
A33: A16484 | B33: 41652 | C33: LINGDONG | D33: M10 | E33: LING AO | F33: CHINE | G33: RCV - TNC 630 D4 | H33: 56X.EI1469 | I33: 1 | J33: 1 | K33: 6 | L33: 1 | M33: 50 | N33: 1500 | O33: 52 | P33: 53 | Q33: 4 | R33: 72 | S33: 151 | T33: 1001 | U33: 55 | V33: - | W33: ASYNCH | X33: ASYNCH_CAGE | Z33: MS | AB33: {=_xlfn._xlws.FILTER(Projets!I$2:I$823,(Projets!A$2:A$823=A33), "")}
A34: A16537 | B34: 41697 | C34: RCV SPX CU ANNECY | D34: M10 | E34: SPX CLYDE UNION ANNECY | F34: CNPEC YANGJIANG | G34: tnc630 d4 | H34: 56X.EI1469 | I34: 6 | J34: 1 | K34: 6 | L34: 1 | M34: 50 | N34: 1500 | O34: 52 | P34: 53 | Q34: 4 | R34: 72 | S34: 151 | T34: 1001 | U34: 55 | V34: - | W34: ASYNCH | X34: ASYNCH_CAGE | Z34: MS | AB34: {=_xlfn._xlws.FILTER(Projets!I$2:I$823,(Projets!A$2:A$823=A34), "")}
A35: A16561 | B35: 41726 | C35: LINDE TERNI | D35: M10 | E35: LINDE GAS ITALIA S.R.L. | F35: LINDE GAS ITALIA S.R.L. | G35: JEMAC900RS4_6_50 | I35: 1 | J35: 5.7 | K35: 6 | L35: 0.93 | M35: 50 | N35: 1500 | O35: 95 | P35: 84 | Q35: 4 | R35: 120 | S35: IC8A1W7 | T35: 1001 | U35: 55 | V35: - | W35: ASYNCH | X35: ASYNCH_CAGE | Z35: MS | AB35: {=_xlfn._xlws.FILTER(Projets!I$2:I$823,(Projets!A$2:A$823=A35), "")}
A36: A16586 | B36: 41837 | C36: SOC IRAK KUFA | D36: M10 | E36: SOC | F36: SOC | G36: JEMAC 900TL12-6.6-50 | I36: 1 | J36: 3.4 | K36: 6.6 | L36: 0.78 | M36: 50 | N36: 500 | O36: 125 | P36: 112 | Q36: 12 | R36: 108 | S36: 666 | T36: 1001 | U36: 55 | V36: - | W36: ASYNCH | X36: ASYNCH_CAGE | Z36: MS | AB36: {=_xlfn._xlws.FILTER(Projets!I$2:I$823,(Projets!A$2:A$823=A36), "")}
A37: A16605 | B37: 41743 | C37: RRA YANGJIANG 5 ET 6 | D37: M10 | E37: CLYDE UNION PUMPS GLASGOW | F37: CNPEC | G37: rra - tnc 630 - ax - 4 | I37: 4 | J37: 1 | K37: 6 | L37: 1 | M37: 50 | N37: 1500 | O37: 52 | P37: 36 | Q37: 4 | R37: 72 | S37: 151 | T37: 1001 | U37: 55 | V37: - | W37: ASYNCH | X37: ASYNCH_CAGE | Z37: MS | AB37: {=_xlfn._xlws.FILTER(Projets!I$2:I$823,(Projets!A$2:A$823=A37), "")}
A38: A16618 | B38: 41752 | C38: ITER | D38: M30 | E38: COFELY AXIMA | F38: AIR LIQUIDE | G38: Jemac 500RL2_6,6_50 | I38: 6 | J38: 2.5 | K38: 6.6 | L38: 0.894 | M38: 50 | N38: 3000 | O38: 44 | P38: 89 | Q38: 2 | R38: 54 | S38: IC8A1W7 | T38: 1001 | U38: 55 | V38: - | W38: ASYNCH | X38: ASYNCH_CAGE | Z38: MS | AB38: {=_xlfn._xlws.FILTER(Projets!I$2:I$823,(Projets!A$2:A$823=A38), "")}
A39: A16618 | B39: 42192 | C39: ITER | D39: M20 | E39: COFELY AXIMA | F39: AIR LIQUIDE | G39: Jemac 400RXL2_6,6_60 | I39: 3 | J39: 1.1 | K39: 6.6 | L39: 0.91 | M39: 60 | N39: 3600 | O39: 39 | P39: 58 | Q39: 2 | R39: 54 | S39: IC8A1W7 | T39: 1001 | U39: 55 | V39: - | W39: ASYNCH | X39: ASYNCH_CAGE | Z39: MS | AB39: {=_xlfn._xlws.FILTER(Projets!I$2:I$823,(Projets!A$2:A$823=A39), "")}
A40: A16618 | B40: 42192 | C40: ITER | D40: M10 | E40: COFELY AXIMA | F40: AIR LIQUIDE | G40: Jemac 400RL2_6,6_50 | I40: 9 | J40: 0.986 | K40: 6.6 | L40: 0.91 | M40: 50 | N40: 3000 | O40: 39 | P40: 58 | Q40: 2 | R40: 54 | S40: IC8A1W7 | T40: 1001 | U40: 55 | V40: - | W40: ASYNCH | X40: ASYNCH_CAGE | Z40: MS | AB40: {=_xlfn._xlws.FILTER(Projets!I$2:I$823,(Projets!A$2:A$823=A40), "")}
...

Sheet Data
A1: Name | B1: Report Cost Code | C1: Project Id | D1: Total Quantity
A2: MATHIEU ANDRUSZCZAK | B2: 230ETELEC | C2: A15026 | D2: 45.8
A3: ALEX LIXON | B3: 230ETMECA | C3: A15026 | D3: 215.1
A4: CARLA WALLART | B4: 230ETMECA | C4: A15026 | D4: 79.85 | G4: Requête SQL:
A5: CHRISTOPHE MAREE | B5: 230ETMECA | C5: A15026 | D5: 71 | G5: SELECT
A6: MATHIEU ANDRUSZCZAK | B6: 240RD | C6: A15026 | D6: 131.55 | G6: T1.name,
A7: DANIEL LALOY | B7: 240RD | C7: A15026 | D7: 2 | G7: H2.report_cost_code,
A8: VINCENT DEWEZ | B8: 240RD | C8: A15026 | D8: 45.5 | G8: H2.Project_id,
A9: JULIEN FORNARA | B9: 240RD | C9: A15026 | D9: 16.7 | G9: SUM(H2.internal_quantity) AS total_quantity
A10: PHILIPPE LALOY | B10: 240RD | C10: A15026 | D10: 60.2
A11: MAAMAR GACI | B11: 240RD | C11: A15026 | D11: 3 | G11: FROM IFSAPP.Project_transaction H2
A12: CARLA WALLART | B12: 240RD | C12: A15026 | D12: 29.8
A13: RAPHAEL VERDIN | B13: 240RD | C13: A15026 | D13: 14.2 | G13: LEFT JOIN IFSAPP.PERSON_INFO_ALL T1
A14: MARC BERGAMASCO | B14: 240RD | C14: A15026 | D14: 221.3 | G14: ON T1.PERSON_ID = H2.emp_no
A15: CELDRIC BISCHOFF | B15: 230ETMECA | C15: A15045 | D15: 65.5
A16: JOHANN PRONIER | B16: 230ETELEC | C16: A15045 | D16: 49.2 | G16: WHERE
A17: CATHERINE SADI | B17: 230ETMECA | C17: A15045 | D17: 5 | G17: H2.report_cost_type_db = 1
A18: IOSSIF PETROPOULOS | B18: 230ETNQ | C18: A15045 | D18: 9.55 | G18: AND (
A19: DENIS BENICCHIO | B19: 230ETMECA | C19: A15045 | D19: 63.3 | G19: H2.Project_id LIKE 'A1%'
A20: DIDIER SENECAT | B20: 230ETMECA | C20: A15045 | D20: 63 | G20: OR H2.Project_id LIKE 'AN%'
A21: BERNARD JOUNIAUX | B21: 230ETELEC | C21: A15045 | D21: 7.7 | G21: OR H2.Project_id LIKE 'S1%'
A22: KEVIN SCHMITT | B22: 230ETELEC | C22: A15045 | D22: 142.75 | G22: OR H2.Project_id LIKE 'SN%'
A23: CHRISTOPHE SERPILLON | B23: 230ETMECA | C23: A15045 | D23: 245 | G23: OR H2.Project_id LIKE 'X1%'
A24: CARLA WALLART | B24: 230ETMECA | C24: A15045 | D24: 5.85 | G24: OR H2.Project_id LIKE 'XN%'
A25: IOSSIF PETROPOULOS | B25: 230ETMECA | C25: A15045 | D25: 69.1 | G25: OR H2.Project_id LIKE 'V1%'
A26: DOMINIQUE BLAIRON | B26: 230ETMECA | C26: A15045 | D26: 860.25 | G26: OR H2.Project_id LIKE 'VN%'
A27: ALAIN DUCROT | B27: 230ETELEC | C27: A15045 | D27: 15.4 | G27: )
... A31: STEPHANE NICOLAS | B31: 230ETMECA | C31: A15055 | D31: 37.75 | G31: )
A32: MATHIEU ANDRUSZCZAK | B32: 230ETELEC | C32: A15055 | D32: 12
A33: ABDOUSSAMAD AMALLAH | B33: 230ETMECA | C33: A15055 | D33: 89.55 | G33: GROUP BY
A34: ABDOUSSAMAD AMALLAH | B34: 230ETMECA | C34: A15168 | D34: 106.25 | G34: T1.name,
A35: ANDRE HUART | B35: 230ETREGU | C35: A15168 | D35: 29.8 | G35: H2.report_cost_code,
A36: FRANCK LAURENT | B36: 230ETREGU | C36: A15168 | D36: 2 | G36: H2.Project_id
A37: CARLA WALLART | B37: 230ETMECA | C37: A15168 | D37: 15.55
A38: JOHANN PRONIER | B38: 230ETELEC | C38: A15168 | D38: 334.8
A39: STEPHANE NICOLAS | B39: 230ETMECA | C39: A15168 | D39: 3.5
A40: ANDRE HUART | B40: 230ETNQ | C40: A15168 | D40: 4
A41: CYRIL DUBOIS | B41: 230ETMECA | C41: A15168 | D41: 55.7
A42: ANDRE HUART | B42: 230ETMECA | C42: A15168 | D42: 271.35
A43: CARLA WALLART | B43: 240RD | C43: A15173 | D43: 2
...
